{
 "cells": [
  {
   "cell_type": "code",
   "execution_count": 1,
   "metadata": {},
   "outputs": [
    {
     "ename": "RuntimeError",
     "evalue": "asyncio.run() cannot be called from a running event loop",
     "output_type": "error",
     "traceback": [
      "\u001b[0;31m---------------------------------------------------------------------------\u001b[0m",
      "\u001b[0;31mRuntimeError\u001b[0m                              Traceback (most recent call last)",
      "Cell \u001b[0;32mIn [1], line 5\u001b[0m\n\u001b[1;32m      2\u001b[0m \u001b[38;5;28;01mfrom\u001b[39;00m \u001b[38;5;21;01mdocarray\u001b[39;00m \u001b[38;5;28;01mimport\u001b[39;00m DocumentArray\n\u001b[1;32m      4\u001b[0m \u001b[38;5;66;03m# Login to Jina ecosystem\u001b[39;00m\n\u001b[0;32m----> 5\u001b[0m \u001b[43mfinetuner\u001b[49m\u001b[38;5;241;43m.\u001b[39;49m\u001b[43mlogin\u001b[49m\u001b[43m(\u001b[49m\u001b[43m)\u001b[49m\n\u001b[1;32m      7\u001b[0m \u001b[38;5;28mprint\u001b[39m(\u001b[38;5;124m'\u001b[39m\u001b[38;5;124mGajraj\u001b[39m\u001b[38;5;124m'\u001b[39m)\n",
      "File \u001b[0;32m/workspace/.pyenv_mirror/user/current/lib/python3.8/site-packages/finetuner/__init__.py:34\u001b[0m, in \u001b[0;36mlogin\u001b[0;34m()\u001b[0m\n\u001b[1;32m     33\u001b[0m \u001b[39mdef\u001b[39;00m \u001b[39mlogin\u001b[39m():\n\u001b[0;32m---> 34\u001b[0m     ft\u001b[39m.\u001b[39;49mlogin()\n",
      "File \u001b[0;32m/workspace/.pyenv_mirror/user/current/lib/python3.8/site-packages/finetuner/finetuner.py:27\u001b[0m, in \u001b[0;36mFinetuner.login\u001b[0;34m(self)\u001b[0m\n\u001b[1;32m     21\u001b[0m \u001b[39mdef\u001b[39;00m \u001b[39mlogin\u001b[39m(\u001b[39mself\u001b[39m):\n\u001b[1;32m     22\u001b[0m     \u001b[39m\"\"\"Login to Hubble account, initialize a client object\u001b[39;00m\n\u001b[1;32m     23\u001b[0m \u001b[39m    and create a default experiment.\u001b[39;00m\n\u001b[1;32m     24\u001b[0m \n\u001b[1;32m     25\u001b[0m \u001b[39m    Note: Calling `login` is necessary for using finetuner.\u001b[39;00m\n\u001b[1;32m     26\u001b[0m \u001b[39m    \"\"\"\u001b[39;00m\n\u001b[0;32m---> 27\u001b[0m     hubble\u001b[39m.\u001b[39;49mlogin()\n\u001b[1;32m     28\u001b[0m     \u001b[39mself\u001b[39m\u001b[39m.\u001b[39m_init_state()\n",
      "File \u001b[0;32m/workspace/.pyenv_mirror/user/current/lib/python3.8/site-packages/hubble/__init__.py:54\u001b[0m, in \u001b[0;36mlogin\u001b[0;34m(**kwargs)\u001b[0m\n\u001b[1;32m     52\u001b[0m \u001b[39mdef\u001b[39;00m \u001b[39mlogin\u001b[39m(\u001b[39m*\u001b[39m\u001b[39m*\u001b[39mkwargs):\n\u001b[1;32m     53\u001b[0m     \u001b[39m\"\"\"This function guide user to browser log-in and get token.\"\"\"\u001b[39;00m\n\u001b[0;32m---> 54\u001b[0m     asyncio\u001b[39m.\u001b[39;49mrun(Auth\u001b[39m.\u001b[39;49mlogin(\u001b[39m*\u001b[39;49m\u001b[39m*\u001b[39;49mkwargs))\n",
      "File \u001b[0;32m~/.pyenv/versions/3.8.13/lib/python3.8/asyncio/runners.py:33\u001b[0m, in \u001b[0;36mrun\u001b[0;34m(main, debug)\u001b[0m\n\u001b[1;32m      9\u001b[0m \u001b[39m\"\"\"Execute the coroutine and return the result.\u001b[39;00m\n\u001b[1;32m     10\u001b[0m \n\u001b[1;32m     11\u001b[0m \u001b[39mThis function runs the passed coroutine, taking care of\u001b[39;00m\n\u001b[0;32m   (...)\u001b[0m\n\u001b[1;32m     30\u001b[0m \u001b[39m    asyncio.run(main())\u001b[39;00m\n\u001b[1;32m     31\u001b[0m \u001b[39m\"\"\"\u001b[39;00m\n\u001b[1;32m     32\u001b[0m \u001b[39mif\u001b[39;00m events\u001b[39m.\u001b[39m_get_running_loop() \u001b[39mis\u001b[39;00m \u001b[39mnot\u001b[39;00m \u001b[39mNone\u001b[39;00m:\n\u001b[0;32m---> 33\u001b[0m     \u001b[39mraise\u001b[39;00m \u001b[39mRuntimeError\u001b[39;00m(\n\u001b[1;32m     34\u001b[0m         \u001b[39m\"\u001b[39m\u001b[39masyncio.run() cannot be called from a running event loop\u001b[39m\u001b[39m\"\u001b[39m)\n\u001b[1;32m     36\u001b[0m \u001b[39mif\u001b[39;00m \u001b[39mnot\u001b[39;00m coroutines\u001b[39m.\u001b[39miscoroutine(main):\n\u001b[1;32m     37\u001b[0m     \u001b[39mraise\u001b[39;00m \u001b[39mValueError\u001b[39;00m(\u001b[39m\"\u001b[39m\u001b[39ma coroutine was expected, got \u001b[39m\u001b[39m{!r}\u001b[39;00m\u001b[39m\"\u001b[39m\u001b[39m.\u001b[39mformat(main))\n",
      "\u001b[0;31mRuntimeError\u001b[0m: asyncio.run() cannot be called from a running event loop"
     ]
    }
   ],
   "source": [
    "import finetuner\n",
    "from docarray import DocumentArray\n",
    "\n",
    "# Login to Jina ecosystem\n",
    "finetuner.login()\n",
    "\n",
    "print('Gajraj')"
   ]
  }
 ],
 "metadata": {
  "kernelspec": {
   "display_name": "Python 3.8.13 64-bit ('shims')",
   "language": "python",
   "name": "python3"
  },
  "language_info": {
   "codemirror_mode": {
    "name": "ipython",
    "version": 3
   },
   "file_extension": ".py",
   "mimetype": "text/x-python",
   "name": "python",
   "nbconvert_exporter": "python",
   "pygments_lexer": "ipython3",
   "version": "3.8.13"
  },
  "orig_nbformat": 4,
  "vscode": {
   "interpreter": {
    "hash": "9ac03a0a6051494cc606d484d27d20fce22fb7b4d169f583271e11d5ba46a56e"
   }
  }
 },
 "nbformat": 4,
 "nbformat_minor": 2
}
